Workbook

Sheet DB
B3: 0 | C3: UID | G3: txt
B4: 1 | C4: SALE_DATE | D4: วันที่ยื่นซอง | G4: txt
B5: 2 | C5: SALE_HOSPITAL | D5: โรงพยาบาล | G5: txt
B6: 3 | C6: SALE_DEPARTMENT | D6: หน่วยงาน | G6: txt
B7: 4 | C7: SALE_PRODUCT_MODEL_ID | G7: sel
B8: 5 | C8: SALE_PRODUCT_MODEL_NAME | D8: โมเดล | G8: sel
B9: 6 | C9: PRODUCT_NAME | D9: สินค้า | G9: sel
B10: 7 | C10: BRAND_NAME | D10: แบรนด์
B11: 8 | C11: SALE_UNIT_PRICE | D11: ราคา/หน่วย
B12: 9 | C12: SALE_QTY | D12: จำนวน
B13: 10 | C13: SALE_TOTAL_PRICE | D13: ราคารวม Vat
B14: 11 | C14: SALE_CUSTSTATE_ID
B15: 12 | C15: CUSTSTATE_NAME | D15: สถานะลูกค้า
B16: 13 | C16: SALE_ORDERSTATE_ID
B17: 14 | C17: ORDERSTATE_NAME | D17: สถานะสินค้า
B18: 15 | C18: SALE_ESTIMATE_IN | D18: คาดการณ์สินค้าเข้า
B19: 16 | C19: SALE_STAFF_ID
B20: 17 | C20: SALE_STAFF_AM_ID
B21: 18 | C21: SALE_STAFF_BM_ID
B22: 19 | C22: SALE_STAFF_SUP_ID
B23: 20 | C23: SALE_ORDER_TYPE
B24: 21 | C24: ORDERTYPE_NAME | D24: B2
B25: 22 | C25: SALE_ORDER_YEAR | D25: ปี
B26: 23 | C26: SALE_ORDER_MONTH | D26: เดือน
B27: 24 | C27: SALE_PROB_ID
B28: 25 | C28: ORDERPROB_NAME | D28: ความน่าจะเป็น
B29: 26 | C29: SALE_BUDGET_ID
B30: 27 | C30: BUDGETTYPE_NAME | D30: ประเภทงบ
B31: 28 | C31: STAFF_ID
B32: 29 | C32: STAFF_NAME | D32: พนักงานขาย
B33: 30 | C33: BM_ID
B34: 31 | C34: BM_NAME | D34: BM
B35: 32 | C35: AM_ID
B36: 33 | C36: AM_NAME | D36: AM
B37: 34 | C37: SALE_REMARK | D37: หมายเหตุ
B38: 35 | C38: SALE_CWHEN
B39: 36 | C39: SALE_MWHEN
B40: 37 | C40: SALE_CNAME
B41: 38 | C41: SALE_MNAME

Sheet CODING
A1: CTRL_VARIABLE | B1: JQUERY
A2: ctrl_txt_sale_date | B2: $("#txt_sale_date"); | E2: dim | F2: ctrl_txt_sale_date | G2: as string | H2: - | I2: ="Request.Form("""&F2 &""")" -> Request.Form(" ctrl_txt_sale_date ")
A3: ctrl_txt_sale_hospital | B3: $("#txt_sale_hospital"); | E3: dim | F3: ctrl_txt_sale_hospital | G3: as string | H3: - | I3: ="Request.Form("""&F3 &""")" -> Request.Form(" ctrl_txt_sale_hospital ")
A4: ctrl_txt_txt_sale_department | B4: $("#txt_sale_department"); | E4: dim | F4: ctrl_txt_txt_sale_department | G4: as string | H4: - | I4: ="Request.Form("""&F4 &""")" -> Request.Form(" ctrl_txt_txt_sale_department ")
A5: ctrl_sel_brand_name | B5: $("#sel_brand_name"); | E5: dim | F5: ctrl_sel_brand_name | G5: as string | H5: - | I5: ="Request.Form("""&F5 &""")" -> Request.Form(" ctrl_sel_brand_name ")
A6: ctrl_sel_product_name | B6: $("#sel_product_name"); | E6: dim | F6: ctrl_sel_product_name | G6: as string | H6: - | I6: ="Request.Form("""&F6 &""")" -> Request.Form(" ctrl_sel_product_name ")
A7: ctrl_txt_sale_id | B7: $("# txt_sale_id"); | E7: dim | F7: ctrl_txt_sale_id | G7: as string | H7: - | I7: ="Request.Form("""&F7 &""")" -> Request.Form(" ctrl_txt_sale_id")
A8: ctrl_sel_sale_product_model_name | B8: $("#sel_sale_product_model_name"); | E8: dim | F8: ctrl_sel_sale_product_model_name | G8: as string | H8: - | I8: ="Request.Form("""&F8 &""")" -> Request.Form(" ctrl_sel_sale_product_model_name ")
A9: ctrl_txt_sale_unit_price | B9: $("#txt_sale_unit_price"); | E9: dim | F9: ctrl_txt_sale_unit_price | G9: as string | H9: - | I9: ="Request.Form("""&F9 &""")" -> Request.Form(" ctrl_txt_sale_unit_price ")
A10: ctrl_txt_sale_qty | B10: $("#txt_sale_qty"); | E10: dim | F10: ctrl_txt_sale_qty | G10: as string | H10: - | I10: ="Request.Form("""&F10 &""")" -> Request.Form(" ctrl_txt_sale_qty ")
A11: ctrl_txt_sale_total_price | B11: $("#txt_sale_total_price"); | E11: dim | F11: ctrl_txt_sale_total_price | G11: as string | H11: - | I11: ="Request.Form("""&F11 &""")" -> Request.Form(" ctrl_txt_sale_total_price ")
A12: ctrl_sel_custstate_name | B12: $("#sel_custstate_name"); | E12: dim | F12: ctrl_sel_custstate_name | G12: as string | H12: - | I12: ="Request.Form("""&F12 &""")" -> Request.Form(" ctrl_sel_custstate_name ")
A13: ctrl_sel_orderstate_name | B13: $("#sel_orderstate_name"); | E13: dim | F13: ctrl_sel_orderstate_name | G13: as string | H13: - | I13: ="Request.Form("""&F13 &""")" -> Request.Form(" ctrl_sel_orderstate_name ")
... A24: ctrl_txt_sale_remark | B24: $("#txt_sale_remark"); | E24: dim | F24: ctrl_txt_sale_remark | G24: as string | H24: - | I24: ="Request.Form("""&F24 &""")" -> Request.Form(" ctrl_txt_sale_remark ")

Sheet Staff
B1: STAFF | C1: NAME | D1: login | E1: Pass | F1: BOSSID | G1: BOSS NAME | H1: TYPES | I1: Column1 | J1: EMAIL | K1: AREA | L1: LEVEL | M1: NICK_NAME | N1: TYPE | O1: GROUP
B2: 300001 | C2: วิโรจน์ วสุศุทธิกุลกานต์ | D2: 300001 | E2: 300001 | H2: MD | J2: viroj2516@gmail.com | K2: Thailand | L2: L0 | M2: โต | N2: CORPORATE | O2: ALL
B3: 313001 | C3: ฐิติรัตน์ ตางาม | D3: 313001 | E3: 313001 | F3: 300001 | G3: วิโรจน์ วสุศุทธิกุลกานต์ | H3: BM | J3: opor6655@gmail.com | K3: Thailand | L3: L1 | M3: ปอ | N3: BM | O3: ALL
B4: 314001 | C4: ธเนส ภูมิสุราษฎร์ | D4: 314001 | E4: 314001 | F4: 300001 | G4: วิโรจน์ วสุศุทธิกุลกานต์ | H4: AM | J4: tanetoh@gmail.com | K4: Thailand | L4: L1 | M4: โอ๋ | N4: AM | O4: ALL
B5: 314002 | C5: วุฒิชัย สุนทรานนท์ | D5: 314002 | E5: 314002 | F5: 313001 | G5: ฐิติรัตน์ ตางาม | H5: BM | J5: saintmed.ws@gmail.com | K5: THAILAND | L5: L2 | M5: บอส | N5: BM1 | O5: BRAND
B6: 314003 | C6: สันต์ เบ็ญจกาญจน์ | D6: 314003 | E6: 314003 | F6: 314001 | G6: ธเนส ภูมิสุราษฎร์ | H6: AM | J6: san.st.med@gmail.com | K6: South | L6: L2 | M6: หนุ่ม | N6: AM1 | O6: GROUP1
B7: 314004 | C7: เฉลิมลักษณ์ รักษ์อารีกุล | D7: 314004 | E7: 314004 | F7: 314001 | G7: ธเนส ภูมิสุราษฎร์ | H7: AM | J7: chalermluck741@gmail.com | K7: Bangkok | L7: L2 | M7: เอส | N7: AM2 | O7: GROUP1
B8: 314006 | C8: ปรีชา แก้ววิชิต | D8: 314006 | E8: 314006 | F8: 314001 | G8: ธเนส ภูมิสุราษฎร์ | H8: AM | J8: pkpk2412@gmail.com | K8: North East | L8: L2 | M8: ป๋าชา | N8: AM3 | O8: GROUP1
B9: 314007 | C9: มนตรี รายพิมาย | D9: 314007 | E9: 314007 | F9: 314001 | G9: ธเนส ภูมิสุราษฎร์ | H9: AM | J9: montri.rai@gmail.com | K9: Central | L9: L2 | M9: ต้น | N9: AM4 | O9: GROUP1
B10: 314008 | C10: ศิริลักษณ์ ศุภวัฒน์ภิญโญ | D10: 314008 | E10: 314008 | F10: 314001 | G10: ธเนส ภูมิสุราษฎร์ | H10: AM | J10: siriluckper@gmail.com | K10: North | L10: L2 | M10: ลักษณ์ | N10: AM5 | O10: GROUP1
B11: 314009 | C11: ทิวาพร คาดีวี | D11: 314009 | E11: 314009 | F11: 313001 | G11: ฐิติรัตน์ ตางาม | H11: BM | J11: tiwaka2522@gmail.com | K11: THAILAND | L11: L2 | M11: อร | N11: BM2 | O11: BRAND | Q11: ST
B12: 314039 | C12: กรกิจ โพธิ์สวัสดิ์ | D12: 314039 | E12: 314039 | F12: 314001 | G12: ธเนส ภูมิสุราษฎร์ | H12: AM | J12: koragit.potsawat@gmail.com | K12: Under North | L12: L2 | M12: อู๋ | N12: AM6 | O12: GROUP1
B13: 314050 | C13: อดิศร คำภาทู | D13: 314050 | E13: 314050 | F13: 313001 | G13: ฐิติรัตน์ ตางาม | H13: BM | J13: adisorn5452@gmail.com | K13: THAILAND | L13: L2 | M13: ศร | N13: BM3 | O13: BRAND
B14: 314083 | C14: อัญชรี ทีหอคำ | D14: 314083 | E14: 314083 | F14: 313001 | G14: ฐิติรัตน์ ตางาม | H14: BM | J14: ancharee.teehokun@gmail.com | K14: THAILAND | L14: L2 | M14: อ้น | N14: BM4 | O14: GROUP1
B15: 314112 | C15: สุภาวิณี แย้มสุวรรณา | D15: 314112 | E15: 314112 | F15: 313001 | G15: ฐิติรัตน์ ตางาม | H15: BM | J15: suphavinee.m@gmail.com | K15: THAILAND | L15: L2 | M15: มิ้ว | N15: BM5 | O15: BRAND
B16: 314113 | C16: กชกร ดวงบุญ | D16: 314113 | E16: 314113 | F16: 313001 | G16: ฐิติรัตน์ ตางาม | H16: BM | J16: noon00kotchakorn@gmail.com | K16: THAILAND | L16: L2 | M16: นุ่น | N16: BM6 | O16: BRAND
B17: 314116 | C17: กัญญ์วรา เลิศศุภวิทย์นภา | D17: 314116 | E17: 314116 | F17: 314059 | G17: ศุภวัฒน์ จิรประเสริฐสม | H17: BM | J17: kanwaralers@gmail.com | K17: THAILAND | L17: L2 | M17: เอื้อ | N17: BM7 | O17: BRAND
B18: 313001_2 | C18: ฐิติรัตน์2 ตางาม | D18: 313001_2 | E18: 313001_2 | F18: 314001 | G18: ธเนส ภูมิสุราษฎร์ | H18: AM | J18: opor66552@gmail.com | K18: Thailand | L18: L2 | M18: ปอ | N18: AM7 | O18: GROUP2
B19: 313016 | C19: สาวิณี แซ่เฮ้ง | D19: 313016 | E19: 313016 | F19: 313001_2 | G19: ฐิติรัตน์2 ตางาม | H19: AM | J19: savinee4600@gmail.com | K19: Thailand | L19: L3 | M19: รัตน์ | N19: AM7 | O19: GROUP2
B20: 313018 | C20: โชติรส ดินดำ | D20: 313018 | E20: 313018 | F20: 314007 | G20: มนตรี รายพิมาย | H20: AM | J20: berrychihi@gmail.com | K20: North East | L20: L3 | M20: แอ้ | N20: AM4 | O20: GROUP1
B21: 313023 | C21: ธีรศิษฏ์ ปลิวมา | D21: 313023 | E21: 313023 | F21: 314039 | G21: กรกิจ โพธิ์สวัสดิ์ | H21: AM | J21: theerasit12@gmail.com | K21: Under North | L21: L3 | M21: สิท | N21: AM6 | O21: GROUP1
B22: 314013 | C22: นลชนัท ศรีนาค | D22: 314013 | E22: 314013 | F22: 314004 | G22: เฉลิมลักษณ์ รักษ์อารีกุล | H22: AM | J22: nolchanat03@gmail.com | K22: Bangkok | L22: L3 | M22: อ้อม | N22: AM2 | O22: GROUP1
B23: 314022 | C23: ศิริพร กนกภูมิรุจา | D23: 314022 | E23: 314022 | F23: 314004 | G23: เฉลิมลักษณ์ รักษ์อารีกุล | H23: AM | J23: yoyoying.sp@gmail.com | K23: Bangkok | L23: L3 | M23: หญิง | N23: AM2 | O23: GROUP1
B24: 314033 | C24: ฐานิตา บุญรอด | D24: 314033 | E24: 314033 | F24: 314006 | G24: ปรีชา แก้ววิชิต | H24: AM | J24: ThanitaBunrod@gmail.com | K24: North East | L24: L3 | M24: ต้อง | N24: AM3 | O24: GROUP1
B25: 314041 | C25: พีรนิตย์ ประณุทนรพาล | D25: 314041 | E25: 314041 | F25: 314003 | G25: สันต์ เบ็ญจกาญจน์ | H25: AM | J25: ppunchywork@gmail.com | K25: South | L25: L3 | M25: พั้นซ์ | N25: AM1 | O25: GROUP1
B26: 314044 | C26: นุรอาบีดิน มะรานอ | D26: 314044 | E26: 314044 | F26: 314003 | G26: สันต์ เบ็ญจกาญจน์ | H26: AM | J26: nurabidin95@gmail.com | K26: South | L26: L3 | M26: นุ | N26: AM1 | O26: GROUP1
B27: 314057 | C27: ปิยรัฎฐ์ สร้อยสุวรรณ | D27: 314057 | E27: 314057 | F27: 314007 | G27: มนตรี รายพิมาย | H27: AM | J27: piyaratparamedic@gmail.com | K27: Central | L27: L3 | M27: ลูกน้ำ | N27: AM4 | O27: GROUP1
B28: 314061 | C28: ขวัญใจ ใจภิภักดิ์ | D28: 314061 | E28: 314061 | F28: 314008 | G28: ศิริลักษณ์ ศุภวัฒน์ภิญโญ | H28: AM | J28: khwanjai088@gmail.com | K28: North | L28: L3 | M28: ขวัญ | N28: AM5 | O28: GROUP1
B29: 314062 | C29: ปถวี วรรธนะภูติ | D29: 314062 | E29: 314062 | F29: 314004 | G29: เฉลิมลักษณ์ รักษ์อารีกุล | H29: AM | J29: patawee.2533@gmail.com | K29: Bangkok | L29: L3 | M29: โอ | N29: AM2 | O29: GROUP1
B30: 314068 | C30: ปรียานุช โตเหมือน | D30: 314068 | E30: 314068 | F30: 314004 | G30: เฉลิมลักษณ์ รักษ์อารีกุล | H30: AM | J30: preeyanoott@gmail.com | K30: Bangkok | L30: L3 | M30: จิงจิง | N30: AM2 | O30: GROUP1
B31: 314069 | C31: โชคชัย รัตนพิมาน | D31: 314069 | E31: 314069 | F31: 314004 | G31: เฉลิมลักษณ์ รักษ์อารีกุล | H31: AM | J31: chokechai.ratt@gmail.com | K31: Bangkok | L31: L3 | M31: บิ๊ก | N31: AM2 | O31: GROUP1
... B56: 315009 | C56: สมใจ เพ็งผล | D56: 315009 | E56: 315009 | F56: 313016 | G56: สาวิณี แซ่เฮ้ง | H56: AM | J56: somjai.ppui@gmail.com | K56: Thailand | L56: L4 | M56: ปุ้ย | N56: AM7.4 | O56: GROUP3
B57: 314022_2 | C57: ศิริพร2 กนกภูมิรุจา | D57: 314022_2 | E57: 314022_2 | F57: 313016 | G57: สาวิณี แซ่เฮ้ง | H57: AM | J57: yoyoying.sp2@gmail.com | K57: Up Country | L57: L4 | M57: หญิง | N57: AM7 | O57: GROUP2
B58: 313004 | C58: พิชชาอร ขาวผ่อง | D58: 313004 | E58: 313004 | F58: 314022_2 | G58: ศิริพร2 กนกภูมิรุจา | H58: AM | J58: phichaonkp@gmail.com | K58: Bangkok | L58: L5 | M58: แพรว | N58: AM7.3 | O58: GROUP2
B59: 313008 | C59: วิชชุดา ศากรณ์ | D59: 313008 | E59: 313008 | F59: 313016 | G59: สาวิณี แซ่เฮ้ง | H59: AM | J59: wichuda.23091982@gmail.com | K59: Bangkok | L59: L4 | M59: 313 | N59: AM7 | O59: GROUP2
B60: 313036 | C60: นฤมล อ่อนอรุณ | D60: 313036 | E60: 313036 | F60: 313014 | G60: นิศารัตน์ เถื่อนสุวรรณ์ | H60: AM | J60: naruemononarun@gmail.com​ | K60: Bangkok | L60: L5 | M60: อุ้ม | N60: AM7.2 | O60: GROUP2
B61: 313045 | C61: พิชญ์ศราการณ์ สุทธิสนธิ์ | D61: 313045 | E61: 313045 | F61: 314022_2 | G61: ศิริพร2 กนกภูมิรุจา | H61: AM | J61: pichsarakarn@gmail.com | K61: Up Country | L61: L5 | M61: ฟ้า | N61: AM7.3 | O61: GROUP2
B62: 314017 | C62: ชัยพร ไตรกลิ่น | D62: 314017 | E62: 314017 | F62: 314022_2 | G62: ศิริพร2 กนกภูมิรุจา | H62: AM | J62: bigcpap@gmail.com | K62: Up Country | L62: L5 | M62: บิ๊ก | N62: AM7.3 | O62: GROUP2
B63: 315014 | C63: สินีนาฎ บัวทัน | D63: 315014 | E63: 315014 | F63: 315009 | G63: สมใจ เพ็งผล | H63: AM | J63: sineenad.maprang@gmail.com | K63: Thailand | L63: L5 | M63: มะปราง | N63: AM7.4 | O63: GROUP3
B64: 315018 | C64: ธนัญภัค เลอลาศ | D64: 315018 | E64: 315018 | F64: 313014 | G64: นิศารัตน์ เถื่อนสุวรรณ์ | H64: AM | J64: sara.play0091@gmail.com​ | K64: Bangkok | L64: L5 | M64: เพล์ | N64: AM7.2 | O64: GROUP2
...

Sheet PRODUCT
A1: Original | J1: Product
A2: ยี่ห้อ | B2: สินค้า | C2: รุ่น | D2: BM Name | J2: ยี่ห้อ | O2: ยี่ห้อ | P2: สินค้า | Q2: BM Name
A3: AOLIKE | B3: ICU Bed | C3: ALK-BA501EZE | D3: วุฒิชัย สุนทรานนท์ | J3: AOLIKE | N3: =VLOOKUP(O3,DB_PRODUCT!$D$2:$E$52,2,FALSE) -> 1 | O3: AOLIKE | P3: ICU Bed | Q3: วุฒิชัย สุนทรานนท์
A4: AOLIKE | B4: Electric Hospital Bed | C4: ALK-BA301EZE | D4: วุฒิชัย สุนทรานนท์ | J4: Aurion | N4: =VLOOKUP(O4,DB_PRODUCT!$D$2:$E$52,2,FALSE) -> 1 | O4: AOLIKE | P4: Electric Hospital Bed | Q4: วุฒิชัย สุนทรานนท์
A5: AOLIKE | B5: Electric Hospital Bed | C5: ALK06-B03P-D | D5: วุฒิชัย สุนทรานนท์ | J5: BeneHert | N5: =VLOOKUP(O5,DB_PRODUCT!$D$2:$E$52,2,FALSE) -> 1 | O5: AOLIKE | P5: 3 Cranks Manual Hospital bed | Q5: วุฒิชัย สุนทรานนท์
A6: AOLIKE | B6: Electric Hospital Bed | C6: ALK06-B329P-D | D6: วุฒิชัย สุนทรานนท์ | J6: Bitmos | N6: =VLOOKUP(O6,DB_PRODUCT!$D$2:$E$52,2,FALSE) -> 1 | O6: AOLIKE | P6: 2 Cranks Manual Hospital bed | Q6: วุฒิชัย สุนทรานนท์
A7: AOLIKE | B7: 3 Cranks Manual Hospital bed | C7: ALK-AA301FZE | D7: วุฒิชัย สุนทรานนท์ | J7: Brayden | N7: =VLOOKUP(O7,DB_PRODUCT!$D$2:$E$52,2,FALSE) -> 1 | O7: AOLIKE | P7: Orthopedics Bed | Q7: วุฒิชัย สุนทรานนท์
A8: AOLIKE | B8: 3 Cranks Manual Hospital bed | C8: ALK06-A329P-B | D8: วุฒิชัย สุนทรานนท์ | J8: Casmed | N8: =VLOOKUP(O8,DB_PRODUCT!$D$2:$E$52,2,FALSE) -> 1 | O8: AOLIKE | P8: Emergency Stretcher | Q8: วุฒิชัย สุนทรานนท์
A9: AOLIKE | B9: 3 Cranks Manual Hospital bed | C9: ALK06-A328P | D9: วุฒิชัย สุนทรานนท์ | J9: Defibtech | N9: =VLOOKUP(O9,DB_PRODUCT!$D$2:$E$52,2,FALSE) -> 1 | O9: AOLIKE | P9: Bedside Cabinet | Q9: วุฒิชัย สุนทรานนท์
A10: AOLIKE | B10: 3 Cranks Manual Hospital bed | C10: ALK06-A328L | D10: วุฒิชัย สุนทรานนท์ | J10: Deltex | N10: =VLOOKUP(O10,DB_PRODUCT!$D$2:$E$52,2,FALSE) -> 1 | O10: AOLIKE | P10: Overbed | Q10: วุฒิชัย สุนทรานนท์
A11: AOLIKE | B11: 2 Cranks Manual Hospital bed | C11: ALK-AA201FBL | D11: วุฒิชัย สุนทรานนท์ | J11: EKEAIR | N11: =VLOOKUP(O11,DB_PRODUCT!$D$2:$E$52,2,FALSE) -> 1 | O11: AOLIKE | P11: ALK06-B03P-D | Q11: วุฒิชัย สุนทรานนท์
A12: AOLIKE | B12: 2 Cranks Manual Hospital bed | C12: ALK06-A232P | D12: วุฒิชัย สุนทรานนท์ | J12: Ergoline | N12: =VLOOKUP(O12,DB_PRODUCT!$D$2:$E$52,2,FALSE) -> 1 | O12: AOLIKE | P12: Manual Hospital bed | Q12: วุฒิชัย สุนทรานนท์
A13: AOLIKE | B13: Orthopedics Bed | C13: ALK06-A666 | D13: วุฒิชัย สุนทรานนท์ | J13: Famed | N13: =VLOOKUP(O13,DB_PRODUCT!$D$2:$E$52,2,FALSE) -> 1 | O13: AOLIKE | P13: Stretcher | Q13: วุฒิชัย สุนทรานนท์
A14: AOLIKE | B14: Emergency Stretcher | C14: ALK06-A329Z-B | D14: วุฒิชัย สุนทรานนท์ | J14: Freshing Air | N14: =VLOOKUP(O14,DB_PRODUCT!$D$2:$E$52,2,FALSE) -> 1 | O14: AOLIKE | P14: ALK06-A329Z-B | Q14: วุฒิชัย สุนทรานนท์
... A52: Aurion | B52: Medication Trolley | C52: CP/M40 | D52: วุฒิชัย สุนทรานนท์ | J52: Zoll | N52: =VLOOKUP(O52,DB_PRODUCT!$D$2:$E$52,2,FALSE) -> 13 | O52: Geratherm | P52: Spirometer | Q52: อดิศร คำภาทู
A53: BeneHert | B53: AED | C53: D1 public | D53: ทิวาพร คาดีวี | N53: =VLOOKUP(O53,DB_PRODUCT!$D$2:$E$52,2,FALSE) -> 14 | O53: HugeMed | P53: Video Laryngoscope | Q53: ทิวาพร คาดีวี
A54: Bitmos | B54: Bitmos | C54: Sat801 | D54: ธเนส ภูมิสุราษฎร์ | N54: =VLOOKUP(O54,DB_PRODUCT!$D$2:$E$52,2,FALSE) -> 14 | O54: Hugemed | P54: Video Laryngoscope | Q54: วุฒิชัย สุนทรานนท์
A55: Bitmos | B55: Bitmos | C55: Accessorie | D55: ธเนส ภูมิสุราษฎร์ | N55: =VLOOKUP(O55,DB_PRODUCT!$D$2:$E$52,2,FALSE) -> 15 | O55: Hypnus | P55: CPAP | Q55: ฐิติรัตน์ ตางาม
A56: Bitmos | B56: Bitmos | C56: Sat801 | D56: ธเนส ภูมิสุราษฎร์2 | N56: =VLOOKUP(O56,DB_PRODUCT!$D$2:$E$52,2,FALSE) -> 15 | O56: Hypnus | P56: BIPAP | Q56: ฐิติรัตน์ ตางาม
A57: Bitmos | B57: Bitmos | C57: Accessorie | D57: ธเนส ภูมิสุราษฎร์2 | N57: =VLOOKUP(O57,DB_PRODUCT!$D$2:$E$52,2,FALSE) -> 16 | O57: ICARELIFE | P57: Powered Air Purifing Respirator | Q57: สุภาวิณี แย้มสุวรรณา
A58: Bitmos | B58: Bitmos | C58: Sat805 | D58: ธเนส ภูมิสุราษฎร์ | N58: =VLOOKUP(O58,DB_PRODUCT!$D$2:$E$52,2,FALSE) -> 17 | O58: IN BCA | P58: Face Thermometer | Q58: สุภาวิณี แย้มสุวรรณา
A59: Brayden | B59: CPR Manikin | C59: หุ่นแบบมีไฟ | D59: ทิวาพร คาดีวี | N59: =VLOOKUP(O59,DB_PRODUCT!$D$2:$E$52,2,FALSE) -> 18 | O59: Inspired | P59: O2FLO | Q59: ฐิติรัตน์ ตางาม
A60: Brayden | B60: CPR Manikin | C60: หุ่นแบบไม่มีไฟ | D60: ทิวาพร คาดีวี | N60: =VLOOKUP(O60,DB_PRODUCT!$D$2:$E$52,2,FALSE) -> 18 | O60: inspired | P60: high flow therapyoxygen | Q60: ฐิติรัตน์ ตางาม
A61: Brayden | B61: CPR Manikin | C61: หุ่น brayden pro | D61: ทิวาพร คาดีวี | N61: =VLOOKUP(O61,DB_PRODUCT!$D$2:$E$52,2,FALSE) -> 19 | O61: JingDong | P61: Emergency Trolley | Q61: วุฒิชัย สุนทรานนท์
A62: Brayden | B62: CPR Manikin | C62: หุ่นเด็ก | D62: ทิวาพร คาดีวี | N62: =VLOOKUP(O62,DB_PRODUCT!$D$2:$E$52,2,FALSE) -> 19 | O62: JingDong | P62: Anesthesia Trolley | Q62: วุฒิชัย สุนทรานนท์
A63: Brayden | B63: CPR Manikin | C63: Brayden Pro | D63: ทิวาพร คาดีวี | N63: =VLOOKUP(O63,DB_PRODUCT!$D$2:$E$52,2,FALSE) -> 19 | O63: JingDong | P63: Nursing Trolley | Q63: วุฒิชัย สุนทรานนท์
A64: Casmed | B64: Casmed | C64: Casmed740 | D64: ธเนส ภูมิสุราษฎร์ | N64: =VLOOKUP(O64,DB_PRODUCT!$D$2:$E$52,2,FALSE) -> 19 | O64: Jingdong | P64: Treatment Trolley | Q64: วุฒิชัย สุนทรานนท์
... A154: Mindray | B154: Mindray Ventilator | C154: SV600 | D154: ฐิติรัตน์ ตางาม | N154: =VLOOKUP(O154,DB_PRODUCT!$D$2:$E$52,2,FALSE) -> 48 | O154: Welch Allyn | P154: GS 600 | Q154: กชกร ดวงบุญ
A155: Mindray | B155: Mindray Monitor | C155: ePM10 | D155: ธเนส ภูมิสุราษฎร์ | N155: =VLOOKUP(O155,DB_PRODUCT!$D$2:$E$52,2,FALSE) -> 48 | O155: Welch Allyn | Q155: อดิศร คำภาทู
A156: Mindray | B156: Mindray Monitor | C156: ePM12 | D156: ธเนส ภูมิสุราษฎร์ | N156: =VLOOKUP(O156,DB_PRODUCT!$D$2:$E$52,2,FALSE) -> 48 | O156: Welch Allyn | P156: Fiber Optic Handle Set LED | Q156: กชกร ดวงบุญ
A157: Mindray | B157: Mindray Monitor | C157: ePM 15 | D157: ธเนส ภูมิสุราษฎร์ | N157: =VLOOKUP(O157,DB_PRODUCT!$D$2:$E$52,2,FALSE) -> 48 | O157: Welch Allyn | Q157: กชกร ดวงบุญ
A158: Mindray | B158: Mindray Monitor | C158: iMEC 8 | D158: ธเนส ภูมิสุราษฎร์ | N158: =VLOOKUP(O158,DB_PRODUCT!$D$2:$E$52,2,FALSE) -> 48 | O158: Welch Allyn | P158: Accessories | Q158: ฐิติรัตน์ ตางาม
A159: Mindray | B159: Mindray Monitor | C159: iMEC10 | D159: ธเนส ภูมิสุราษฎร์ | N159: =VLOOKUP(O159,DB_PRODUCT!$D$2:$E$52,2,FALSE) -> 48 | O159: Welch Allyn | P159: Laryngoscope | Q159: ธเนส ภูมิสุราษฎร์
A160: Mindray | B160: Mindray Monitor | C160: iMEC12 | D160: ธเนส ภูมิสุราษฎร์ | N160: =VLOOKUP(O160,DB_PRODUCT!$D$2:$E$52,2,FALSE) -> 48 | O160: Welch Allyn | P160: Opthalmoscope | Q160: กชกร ดวงบุญ
A161: Mindray | B161: Mindray Monitor | C161: iMEC 15 | D161: ธเนส ภูมิสุราษฎร์ | N161: =VLOOKUP(O161,DB_PRODUCT!$D$2:$E$52,2,FALSE) -> 48 | O161: Welch Allyn | P161: ชุดตรวจติดผนัง | Q161: กชกร ดวงบุญ
A162: Mindray | B162: Mindray Ventilator | C162: SV300 | D162: ฐิติรัตน์ ตางาม | N162: =VLOOKUP(O162,DB_PRODUCT!$D$2:$E$52,2,FALSE) -> 48 | O162: Welch Allyn | P162: Ophthalmoscope | Q162: ฐิติรัตน์ ตางาม
A163: Mindray | B163: Mindray Defibrillator | C163: D3 Sat | D163: ทิวาพร คาดีวี | N163: =VLOOKUP(O163,DB_PRODUCT!$D$2:$E$52,2,FALSE) -> 48 | O163: Welch Allyn | P163: Welch Allyn | Q163: กชกร ดวงบุญ
A164: Mindray | B164: Mindray Defibrillator | C164: CMS+ Defibrillator | D164: ธเนส ภูมิสุราษฎร์ | N164: =VLOOKUP(O164,DB_PRODUCT!$D$2:$E$52,2,FALSE) -> 48 | O164: Welch Allyn | P164: Diagnostic Set | Q164: สุภาวิณี แย้มสุวรรณา
A165: Mindray | B165: Mindray pendant | C165: Hyport3000 Double arm | D165: ธเนส ภูมิสุราษฎร์ | N165: =VLOOKUP(O165,DB_PRODUCT!$D$2:$E$52,2,FALSE) -> 48 | O165: Welch Allyn | P165: ชุดตรวจหูตา ชุดที่5 | Q165: กชกร ดวงบุญ
A166: Mindray | B166: Mindray Ultrasound | C166: TE7 | D166: อัญชรี ทีหอคำ | N166: =VLOOKUP(O166,DB_PRODUCT!$D$2:$E$52,2,FALSE) -> 48 | O166: Welch Allyn | P166: Otoscope Specula | Q166: กชกร ดวงบุญ
...

Sheet PIVOT_PRODUCT
A3: Row Labels | B3: Count of รุ่น
A4: 2 Cranks Manual Hospital bed | B4: 2
A5: 3 Cranks Manual Hospital bed | B5: 5
A6: Accessories | B6: 10
A7: AED | B7: 9
A8: ALK BA301EZE | B8: 1
A9: ALk BA301EZE(CR) | B9: 1
A10: ALK06-A328S-E | B10: 1
A11: ALK06-A329P-B | B11: 2
A12: ALK06-A329Z-B | B12: 1
A13: ALK06-AT3 | B13: 1
A14: ALK06-B03PD | B14: 1
A15: ALK06-B03P-D | B15: 2
... A143: Grand Total | B143: 720

Sheet DB_PRODUCT
C1: BRAND | J1: MODEL | Q1: MODEL
C2: 1 | D2: AOLIKE | E2: 1 | J2: BRANDID | K2: ยี่ห้อ | L2: สินค้า | M2: BM Name | N2: BM_ID | Q2: BRANDID | R2: สินค้า | S2: BM_ID
C3: 2 | D3: Aurion | E3: 2 | J3: 1 | K3: AOLIKE | L3: ICU Bed | M3: วุฒิชัย สุนทรานนท์ | N3: 314002 | Q3: 1 | R3: ICU Bed | S3: 314002
C4: 3 | D4: BeneHert | E4: 3 | J4: 1 | K4: AOLIKE | L4: Electric Hospital Bed | M4: วุฒิชัย สุนทรานนท์ | N4: 314002 | Q4: 1 | R4: Electric Hospital Bed | S4: 314002
C5: 4 | D5: Bitmos | E5: 4 | J5: 1 | K5: AOLIKE | L5: 3 Cranks Manual Hospital bed | M5: วุฒิชัย สุนทรานนท์ | N5: 314002 | Q5: 1 | R5: 3 Cranks Manual Hospital bed | S5: 314002
C6: 5 | D6: Brayden | E6: 5 | J6: 1 | K6: AOLIKE | L6: 2 Cranks Manual Hospital bed | M6: วุฒิชัย สุนทรานนท์ | N6: 314002 | Q6: 1 | R6: 2 Cranks Manual Hospital bed | S6: 314002
C7: 6 | D7: Casmed | E7: 6 | J7: 1 | K7: AOLIKE | L7: Orthopedics Bed | M7: วุฒิชัย สุนทรานนท์ | N7: 314002 | Q7: 1 | R7: Orthopedics Bed | S7: 314002
C8: 7 | D8: Defibtech | E8: 7 | J8: 1 | K8: AOLIKE | L8: Emergency Stretcher | M8: วุฒิชัย สุนทรานนท์ | N8: 314002 | Q8: 1 | R8: Emergency Stretcher | S8: 314002
C9: 8 | D9: Deltex | E9: 8 | J9: 1 | K9: AOLIKE | L9: Bedside Cabinet | M9: วุฒิชัย สุนทรานนท์ | N9: 314002 | Q9: 1 | R9: Bedside Cabinet | S9: 314002
C10: 9 | D10: EKEAIR | E10: 9 | J10: 1 | K10: AOLIKE | L10: Overbed | M10: วุฒิชัย สุนทรานนท์ | N10: 314002 | Q10: 1 | R10: Overbed | S10: 314002
C11: 10 | D11: Ergoline | E11: 10 | J11: 1 | K11: AOLIKE | L11: ALK06-B03P-D | M11: วุฒิชัย สุนทรานนท์ | N11: 314002 | Q11: 1 | R11: ALK06-B03P-D | S11: 314002
C12: 11 | D12: Famed | E12: 11 | J12: 1 | K12: AOLIKE | L12: Manual Hospital bed | M12: วุฒิชัย สุนทรานนท์ | N12: 314002 | Q12: 1 | R12: Manual Hospital bed | S12: 314002
C13: 12 | D13: Freshing Air | E13: 12 | J13: 1 | K13: AOLIKE | L13: Stretcher | M13: วุฒิชัย สุนทรานนท์ | N13: 314002 | Q13: 1 | R13: Stretcher | S13: 314002
C14: 13 | D14: Geratherm | E14: 13 | J14: 1 | K14: AOLIKE | L14: ALK06-A329Z-B | M14: วุฒิชัย สุนทรานนท์ | N14: 314002 | Q14: 1 | R14: ALK06-A329Z-B | S14: 314002
... C51: 50 | D51: Zoll | E51: 50 | J51: 13 | K51: Geratherm | L51: Pulmonaray Function Test(PFT) | M51: อดิศร คำภาทู | N51: 314050 | Q51: 13 | R51: Pulmonaray Function Test(PFT) | S51: 314050
C52: NULL | D52: NULL | E52: NULL | J52: 13 | K52: Geratherm | L52: Spirometer | M52: อดิศร คำภาทู | N52: 314050 | Q52: 13 | R52: Spirometer | S52: 314050
J53: 14 | K53: HugeMed | L53: Video Laryngoscope | M53: ทิวาพร คาดีวี | N53: 314009 | Q53: 14 | R53: Video Laryngoscope | S53: 314009
J54: 14 | K54: Hugemed | L54: Video Laryngoscope | M54: วุฒิชัย สุนทรานนท์ | N54: 314002 | Q54: 14 | R54: Video Laryngoscope | S54: 314002
J55: 15 | K55: Hypnus | L55: CPAP | M55: ฐิติรัตน์ ตางาม | N55: 313001 | Q55: 15 | R55: CPAP | S55: 313001
J56: 15 | K56: Hypnus | L56: BIPAP | M56: ฐิติรัตน์ ตางาม | N56: 313001 | Q56: 15 | R56: BIPAP | S56: 313001
J57: 16 | K57: ICARELIFE | L57: Powered Air Purifing Respirator | M57: สุภาวิณี แย้มสุวรรณา | N57: 314112 | Q57: 16 | R57: Powered Air Purifing Respirator | S57: 314112
J58: 17 | K58: IN BCA | L58: Face Thermometer | M58: สุภาวิณี แย้มสุวรรณา | N58: 314112 | Q58: 17 | R58: Face Thermometer | S58: 314112
J59: 18 | K59: Inspired | L59: O2FLO | M59: ฐิติรัตน์ ตางาม | N59: 313001 | Q59: 18 | R59: O2FLO | S59: 313001
J60: 18 | K60: inspired | L60: high flow therapyoxygen | M60: ฐิติรัตน์ ตางาม | N60: 313001 | Q60: 18 | R60: high flow therapyoxygen | S60: 313001
J61: 19 | K61: JingDong | L61: Emergency Trolley | M61: วุฒิชัย สุนทรานนท์ | N61: 314002 | Q61: 19 | R61: Emergency Trolley | S61: 314002
J62: 19 | K62: JingDong | L62: Anesthesia Trolley | M62: วุฒิชัย สุนทรานนท์ | N62: 314002 | Q62: 19 | R62: Anesthesia Trolley | S62: 314002
J63: 19 | K63: JingDong | L63: Nursing Trolley | M63: วุฒิชัย สุนทรานนท์ | N63: 314002 | Q63: 19 | R63: Nursing Trolley | S63: 314002
J64: 19 | K64: Jingdong | L64: Treatment Trolley | M64: วุฒิชัย สุนทรานนท์ | N64: 314002 | Q64: 19 | R64: Treatment Trolley | S64: 314002
... J154: 48 | K154: Welch Allyn | L154: GS 600 | M154: กชกร ดวงบุญ | N154: 314113 | Q154: 48 | R154: GS 600 | S154: 314113
J155: 48 | K155: Welch Allyn | M155: อดิศร คำภาทู | N155: 314050 | Q155: 48 | R155: Fiber Optic Handle Set LED | S155: 314113
J156: 48 | K156: Welch Allyn | L156: Fiber Optic Handle Set LED | M156: กชกร ดวงบุญ | N156: 314113 | Q156: 48 | R156: Accessories | S156: 313001
J157: 48 | K157: Welch Allyn | M157: กชกร ดวงบุญ | N157: 314113 | Q157: 48 | R157: Laryngoscope | S157: 314001
J158: 48 | K158: Welch Allyn | L158: Accessories | M158: ฐิติรัตน์ ตางาม | N158: 313001 | Q158: 48 | R158: Opthalmoscope | S158: 314113
J159: 48 | K159: Welch Allyn | L159: Laryngoscope | M159: ธเนส ภูมิสุราษฎร์ | N159: 314001 | Q159: 48 | R159: ชุดตรวจติดผนัง | S159: 314113
J160: 48 | K160: Welch Allyn | L160: Opthalmoscope | M160: กชกร ดวงบุญ | N160: 314113 | Q160: 48 | R160: Ophthalmoscope | S160: 313001
J161: 48 | K161: Welch Allyn | L161: ชุดตรวจติดผนัง | M161: กชกร ดวงบุญ | N161: 314113 | Q161: 48 | R161: Welch Allyn | S161: 314113
J162: 48 | K162: Welch Allyn | L162: Ophthalmoscope | M162: ฐิติรัตน์ ตางาม | N162: 313001 | Q162: 48 | R162: Diagnostic Set | S162: 314112
J163: 48 | K163: Welch Allyn | L163: Welch Allyn | M163: กชกร ดวงบุญ | N163: 314113 | Q163: 48 | R163: ชุดตรวจหูตา ชุดที่5 | S163: 314113
J164: 48 | K164: Welch Allyn | L164: Diagnostic Set | M164: สุภาวิณี แย้มสุวรรณา | N164: 314112 | Q164: 48 | R164: Otoscope Specula | S164: 314113
J165: 48 | K165: Welch Allyn | L165: ชุดตรวจหูตา ชุดที่5 | M165: กชกร ดวงบุญ | N165: 314113 | Q165: 48 | R165: laryngoscope set | S165: 314113
...

Sheet EDIT PRIVILEGE
A1: AM
A2: SID | B2: D | C2: Column1
A3: 314093 | B3: ="(SALE_STAFF_ID = '" & Table2[[#This Row],[SID]] & "')" -> (SALE_STAFF_ID = '314093') | C3: 1=1 | H3: 314002 | I3: ="((SALE_STAFF_ID = '" & H3 & "') OR (SALE_STAFF_BM_ID = '" & H3 & "'))" -> ((SALE_STAFF_ID = '314002') OR (SALE_STAFF_BM_ID = '314002')) | J3: 1 = 1
A4: 314122 | B4: ="(SALE_STAFF_ID = '" & Table2[[#This Row],[SID]] & "')" -> (SALE_STAFF_ID = '314122') | C4: 1=1 | H4: 314009 | I4: ="((SALE_STAFF_ID = '" & H4 & "') OR (SALE_STAFF_BM_ID = '" & H4 & "'))" -> ((SALE_STAFF_ID = '314009') OR (SALE_STAFF_BM_ID = '314009')) | J4: 1 = 1
A5: 314125 | B5: ="(SALE_STAFF_ID = '" & Table2[[#This Row],[SID]] & "')" -> (SALE_STAFF_ID = '314125') | C5: 1=1 | H5: 314050 | I5: ="((SALE_STAFF_ID = '" & H5 & "') OR (SALE_STAFF_BM_ID = '" & H5 & "'))" -> ((SALE_STAFF_ID = '314050') OR (SALE_STAFF_BM_ID = '314050')) | J5: 1 = 1
A6: 314126 | B6: ="(SALE_STAFF_ID = '" & Table2[[#This Row],[SID]] & "')" -> (SALE_STAFF_ID = '314126') | C6: 1=1 | H6: 314083 | I6: ="((SALE_STAFF_ID = '" & H6 & "') OR (SALE_STAFF_BM_ID = '" & H6 & "'))" -> ((SALE_STAFF_ID = '314083') OR (SALE_STAFF_BM_ID = '314083')) | J6: 1 = 1
A7: 315025 | B7: ="(SALE_STAFF_ID = '" & Table2[[#This Row],[SID]] & "')" -> (SALE_STAFF_ID = '315025') | C7: 1=1 | H7: 314059 | I7: ="((SALE_STAFF_ID = '" & H7 & "') OR (SALE_STAFF_BM_ID = '" & H7 & "'))" -> ((SALE_STAFF_ID = '314059') OR (SALE_STAFF_BM_ID = '314059')) | J7: 1 = 1
A8: 315026 | B8: ="(SALE_STAFF_ID = '" & Table2[[#This Row],[SID]] & "')" -> (SALE_STAFF_ID = '315026') | C8: 1=1 | H8: 314090 | I8: ="((SALE_STAFF_ID = '" & H8 & "') OR (SALE_STAFF_BM_ID = '" & H8 & "'))" -> ((SALE_STAFF_ID = '314090') OR (SALE_STAFF_BM_ID = '314090')) | J8: 1 = 1
A9: 315027 | B9: ="(SALE_STAFF_ID = '" & Table2[[#This Row],[SID]] & "')" -> (SALE_STAFF_ID = '315027') | C9: 1=1
A10: 313002 | B10: ="(SALE_STAFF_ID = '" & Table2[[#This Row],[SID]] & "')" -> (SALE_STAFF_ID = '313002') | C10: 1=1
A11: 313004 | B11: ="(SALE_STAFF_ID = '" & Table2[[#This Row],[SID]] & "')" -> (SALE_STAFF_ID = '313004') | C11: 1=1
A12: 313008 | B12: ="(SALE_STAFF_ID = '" & Table2[[#This Row],[SID]] & "')" -> (SALE_STAFF_ID = '313008') | C12: 1=1
A13: 313014 | B13: ="(SALE_STAFF_ID = '" & Table2[[#This Row],[SID]] & "')" -> (SALE_STAFF_ID = '313014') | C13: 1=1
A14: 313016 | B14: ="(SALE_STAFF_ID = '" & Table2[[#This Row],[SID]] & "')" -> (SALE_STAFF_ID = '313016') | C14: 1=1
A15: 313018 | B15: ="(SALE_STAFF_ID = '" & Table2[[#This Row],[SID]] & "')" -> (SALE_STAFF_ID = '313018') | C15: 1=1
A16: 313023 | B16: ="(SALE_STAFF_ID = '" & Table2[[#This Row],[SID]] & "')" -> (SALE_STAFF_ID = '313023') | C16: 1=1
A17: 313031 | B17: ="(SALE_STAFF_ID = '" & Table2[[#This Row],[SID]] & "')" -> (SALE_STAFF_ID = '313031') | C17: 1=1
A18: 313036 | B18: ="(SALE_STAFF_ID = '" & Table2[[#This Row],[SID]] & "')" -> (SALE_STAFF_ID = '313036') | C18: 1=1
A19: 313037 | B19: ="(SALE_STAFF_ID = '" & Table2[[#This Row],[SID]] & "')" -> (SALE_STAFF_ID = '313037') | C19: 1=1
A20: 313041 | B20: ="(SALE_STAFF_ID = '" & Table2[[#This Row],[SID]] & "')" -> (SALE_STAFF_ID = '313041') | C20: 1=1
... A47: 417007 | B47: ="(SALE_STAFF_ID = '" & Table2[[#This Row],[SID]] & "')" -> (SALE_STAFF_ID = '417007') | C47: 1=1

Sheet Sheet5
C1: NAME | D1: STAFF
C2: วิโรจน์ วสุศุทธิกุลกานต์ | D2: 300001
C3: ฐิติรัตน์ ตางาม | D3: 313001
C4: ธเนส ภูมิสุราษฎร์ | D4: 314001
C5: วุฒิชัย สุนทรานนท์ | D5: 314002
C6: สันต์ เบ็ญจกาญจน์ | D6: 314003
C7: เฉลิมลักษณ์ รักษ์อารีกุล | D7: 314004
C8: ปรีชา แก้ววิชิต | D8: 314006
C9: มนตรี รายพิมาย | D9: 314007
C10: ศิริลักษณ์ ศุภวัฒน์ภิญโญ | D10: 314008
C11: ทิวาพร คาดีวี | D11: 314009
C12: กรกิจ โพธิ์สวัสดิ์ | D12: 314039
C13: อดิศร คำภาทู | D13: 314050
... C17: กัญญ์วรา เลิศศุภวิทย์นภา | D17: 314116
C18: ฐิติรัตน์2 ตางาม | D18: 313001_2
C19: สาวิณี แซ่เฮ้ง | D19: 313016
C20: โชติรส ดินดำ | D20: 313018
C21: ธีรศิษฏ์ ปลิวมา | D21: 313023
C22: นลชนัท ศรีนาค | D22: 314013
C23: ศิริพร กนกภูมิรุจา | D23: 314022
C24: ฐานิตา บุญรอด | D24: 314033
C25: พีรนิตย์ ประณุทนรพาล | D25: 314041
C26: นุรอาบีดิน มะรานอ | D26: 314044
C27: ปิยรัฎฐ์ สร้อยสุวรรณ | D27: 314057
C28: ขวัญใจ ใจภิภักดิ์ | D28: 314061
C29: ปถวี วรรธนะภูติ | D29: 314062
C30: ปรียานุช โตเหมือน | D30: 314068
... C56: สมใจ เพ็งผล | D56: 315009
C57: ศิริพร2 กนกภูมิรุจา | D57: 314022_2
C58: พิชชาอร ขาวผ่อง | D58: 313004
C59: วิชชุดา ศากรณ์ | D59: 313008
C60: นฤมล อ่อนอรุณ | D60: 313036
C61: พิชญ์ศราการณ์ สุทธิสนธิ์ | D61: 313045
C62: ชัยพร ไตรกลิ่น | D62: 314017
C63: สินีนาฎ บัวทัน | D63: 315014
C64: ธนัญภัค เลอลาศ | D64: 315018
C65: ฐิติรัตน์ เพ็ญสุข | D65: 315021
C66: ยุพารัตน์ โสภีพจน์ | D66: 315022
C67: ลักษิกา​ บุญทอง​ | D67: 315023
C68: สุภารวี แย้มนิยม | D68: 207008
...
